Workbook

Sheet Read Me
A1: Wizard Spell Exchange - AL Epic (Forgotten Realms)
A3: Players register their spellbook via the Google Form. Everything else on this workbook is calculated - do not type into any tab except the yellow cells on Copy Planner.
A5: HOW TO USE
A6: 1. Fill in the Google Form at the event (one submission per wizard character).
A7: 2. Open the 'Copy Planner' tab and fill in the yellow cells at the top: your character, their
A8: gold and downtime, and - if levelling up at the end of this Epic - their new wizard level.
A9: 3. Filter the Status column to 'CAN COPY' to see what is available to you.
A10: 4. Tick the 'Want' checkbox. The panel at the top shows what the ticked spells cost, what you
A11: have left, and turns red if either gold or downtime is over budget.
A12: 5. Open 'Copy Log' for the list of what you copied, what it cost, and from
A13: whom - plus a line of text ready to paste into your character log.
A15: THE COST
... A53: - they are never kept in a spellbook.

Sheet Spells
A1: Level | B1: Spell | C1: School | D1: Source | E1: Restriction | F1: GP | G1: DT
A2: 1 | B2: Absorb Elements | C2: Abjuration | D2: Xanathar's Guide | F2: =A2*50 | G2: =IF(A2<=4,1,2)
A3: 1 | B3: Alarm | C3: Abjuration | D3: PHB 2024 | F3: =A3*50 | G3: =IF(A3<=4,1,2)
A4: 1 | B4: Burning Hands | C4: Evocation | D4: PHB 2024 | F4: =A4*50 | G4: =IF(A4<=4,1,2)
A5: 1 | B5: Catapult | C5: Transmutation | D5: Xanathar's Guide | F5: =A5*50 | G5: =IF(A5<=4,1,2)
A6: 1 | B6: Cause Fear | C6: Necromancy | D6: Xanathar's Guide | F6: =A6*50 | G6: =IF(A6<=4,1,2)
A7: 1 | B7: Charm Person | C7: Enchantment | D7: PHB 2024 | F7: =A7*50 | G7: =IF(A7<=4,1,2)
A8: 1 | B8: Chromatic Orb | C8: Evocation | D8: PHB 2024 | F8: =A8*50 | G8: =IF(A8<=4,1,2)
A9: 1 | B9: Color Spray | C9: Illusion | D9: PHB 2024 | F9: =A9*50 | G9: =IF(A9<=4,1,2)
A10: 1 | B10: Comprehend Languages | C10: Divination | D10: PHB 2024 | F10: =A10*50 | G10: =IF(A10<=4,1,2)
A11: 1 | B11: Detect Magic | C11: Divination | D11: PHB 2024 | F11: =A11*50 | G11: =IF(A11<=4,1,2)
A12: 1 | B12: Disguise Self | C12: Illusion | D12: PHB 2024 | F12: =A12*50 | G12: =IF(A12<=4,1,2)
A13: 1 | B13: Earth Tremor | C13: Evocation | D13: Xanathar's Guide | F13: =A13*50 | G13: =IF(A13<=4,1,2)
... A351: 9 | B351: Wish | C351: Conjuration | D351: PHB 2024 | F351: =A351*50 | G351: =IF(A351<=4,1,2)

Sheet Form Responses
A1: Timestamp | B1: Email Address | C1: Player name | D1: Character name | E1: Wizard level | F1: Table number | G1: Wizard subclass | H1: Contact after the event | I1: Level 1 spells | J1: Level 2 spells | K1: Level 3 spells | L1: Level 4 spells | M1: Level 5 spells | N1: Level 6 spells | O1: Level 7 spells | P1: Level 8 spells | Q1: Level 9 spells | R1: Other spells not in the lists above
A27: Google Forms writes into this tab. Do not edit or reorder columns - the whole workbook references them by position.

Sheet Wizards
A1: Character | B1: Player | C1: Wizard level | D1: Max spell level | E1: Table | F1: Subclass | G1: Order of Scribes? | H1: Contact | I1: Spells in book | J1: Rare spells held
A2: =IF(INDEX('Form Responses'!$D$1:$D$200,2)="","",INDEX('Form Responses'!$D$1:$D$200,2)) | B2: =IF($A2="","",INDEX('Form Responses'!$C$1:$C$200,2)) | C2: =IF($A2="","",INDEX('Form Responses'!$E$1:$E$200,2)) | D2: =IF($A2="","",MIN(9,CEILING($C2/2,1))) | E2: =IF($A2="","",INDEX('Form Responses'!$F$1:$F$200,2)) | F2: =IF($A2="","",INDEX('Form Responses'!$G$1:$G$200,2)) | G2: =IF($A2="","",IF(ISNUMBER(SEARCH("Scribes",INDEX('Form Responses'!$G$1:$G$200,2))),"Yes","No")) | H2: =IF($A2="","",INDEX('Form Responses'!$H$1:$H$200,2)) | I2: =IF($A2="","",COUNT(Matrix!$D$2:$D$351)) | J2: =IF($A2="","",COUNTIFS(Matrix!$D$2:$D$351,1,Matrix!$BA$2:$BA$351,1))
A3: =IF(INDEX('Form Responses'!$D$1:$D$200,3)="","",INDEX('Form Responses'!$D$1:$D$200,3)) | B3: =IF($A3="","",INDEX('Form Responses'!$C$1:$C$200,3)) | C3: =IF($A3="","",INDEX('Form Responses'!$E$1:$E$200,3)) | D3: =IF($A3="","",MIN(9,CEILING($C3/2,1))) | E3: =IF($A3="","",INDEX('Form Responses'!$F$1:$F$200,3)) | F3: =IF($A3="","",INDEX('Form Responses'!$G$1:$G$200,3)) | G3: =IF($A3="","",IF(ISNUMBER(SEARCH("Scribes",INDEX('Form Responses'!$G$1:$G$200,3))),"Yes","No")) | H3: =IF($A3="","",INDEX('Form Responses'!$H$1:$H$200,3)) | I3: =IF($A3="","",COUNT(Matrix!$E$2:$E$351)) | J3: =IF($A3="","",COUNTIFS(Matrix!$E$2:$E$351,1,Matrix!$BA$2:$BA$351,1))
A4: =IF(INDEX('Form Responses'!$D$1:$D$200,4)="","",INDEX('Form Responses'!$D$1:$D$200,4)) | B4: =IF($A4="","",INDEX('Form Responses'!$C$1:$C$200,4)) | C4: =IF($A4="","",INDEX('Form Responses'!$E$1:$E$200,4)) | D4: =IF($A4="","",MIN(9,CEILING($C4/2,1))) | E4: =IF($A4="","",INDEX('Form Responses'!$F$1:$F$200,4)) | F4: =IF($A4="","",INDEX('Form Responses'!$G$1:$G$200,4)) | G4: =IF($A4="","",IF(ISNUMBER(SEARCH("Scribes",INDEX('Form Responses'!$G$1:$G$200,4))),"Yes","No")) | H4: =IF($A4="","",INDEX('Form Responses'!$H$1:$H$200,4)) | I4: =IF($A4="","",COUNT(Matrix!$F$2:$F$351)) | J4: =IF($A4="","",COUNTIFS(Matrix!$F$2:$F$351,1,Matrix!$BA$2:$BA$351,1))
A5: =IF(INDEX('Form Responses'!$D$1:$D$200,5)="","",INDEX('Form Responses'!$D$1:$D$200,5)) | B5: =IF($A5="","",INDEX('Form Responses'!$C$1:$C$200,5)) | C5: =IF($A5="","",INDEX('Form Responses'!$E$1:$E$200,5)) | D5: =IF($A5="","",MIN(9,CEILING($C5/2,1))) | E5: =IF($A5="","",INDEX('Form Responses'!$F$1:$F$200,5)) | F5: =IF($A5="","",INDEX('Form Responses'!$G$1:$G$200,5)) | G5: =IF($A5="","",IF(ISNUMBER(SEARCH("Scribes",INDEX('Form Responses'!$G$1:$G$200,5))),"Yes","No")) | H5: =IF($A5="","",INDEX('Form Responses'!$H$1:$H$200,5)) | I5: =IF($A5="","",COUNT(Matrix!$G$2:$G$351)) | J5: =IF($A5="","",COUNTIFS(Matrix!$G$2:$G$351,1,Matrix!$BA$2:$BA$351,1))
A6: =IF(INDEX('Form Responses'!$D$1:$D$200,6)="","",INDEX('Form Responses'!$D$1:$D$200,6)) | B6: =IF($A6="","",INDEX('Form Responses'!$C$1:$C$200,6)) | C6: =IF($A6="","",INDEX('Form Responses'!$E$1:$E$200,6)) | D6: =IF($A6="","",MIN(9,CEILING($C6/2,1))) | E6: =IF($A6="","",INDEX('Form Responses'!$F$1:$F$200,6)) | F6: =IF($A6="","",INDEX('Form Responses'!$G$1:$G$200,6)) | G6: =IF($A6="","",IF(ISNUMBER(SEARCH("Scribes",INDEX('Form Responses'!$G$1:$G$200,6))),"Yes","No")) | H6: =IF($A6="","",INDEX('Form Responses'!$H$1:$H$200,6)) | I6: =IF($A6="","",COUNT(Matrix!$H$2:$H$351)) | J6: =IF($A6="","",COUNTIFS(Matrix!$H$2:$H$351,1,Matrix!$BA$2:$BA$351,1))
A7: =IF(INDEX('Form Responses'!$D$1:$D$200,7)="","",INDEX('Form Responses'!$D$1:$D$200,7)) | B7: =IF($A7="","",INDEX('Form Responses'!$C$1:$C$200,7)) | C7: =IF($A7="","",INDEX('Form Responses'!$E$1:$E$200,7)) | D7: =IF($A7="","",MIN(9,CEILING($C7/2,1))) | E7: =IF($A7="","",INDEX('Form Responses'!$F$1:$F$200,7)) | F7: =IF($A7="","",INDEX('Form Responses'!$G$1:$G$200,7)) | G7: =IF($A7="","",IF(ISNUMBER(SEARCH("Scribes",INDEX('Form Responses'!$G$1:$G$200,7))),"Yes","No")) | H7: =IF($A7="","",INDEX('Form Responses'!$H$1:$H$200,7)) | I7: =IF($A7="","",COUNT(Matrix!$I$2:$I$351)) | J7: =IF($A7="","",COUNTIFS(Matrix!$I$2:$I$351,1,Matrix!$BA$2:$BA$351,1))
A8: =IF(INDEX('Form Responses'!$D$1:$D$200,8)="","",INDEX('Form Responses'!$D$1:$D$200,8)) | B8: =IF($A8="","",INDEX('Form Responses'!$C$1:$C$200,8)) | C8: =IF($A8="","",INDEX('Form Responses'!$E$1:$E$200,8)) | D8: =IF($A8="","",MIN(9,CEILING($C8/2,1))) | E8: =IF($A8="","",INDEX('Form Responses'!$F$1:$F$200,8)) | F8: =IF($A8="","",INDEX('Form Responses'!$G$1:$G$200,8)) | G8: =IF($A8="","",IF(ISNUMBER(SEARCH("Scribes",INDEX('Form Responses'!$G$1:$G$200,8))),"Yes","No")) | H8: =IF($A8="","",INDEX('Form Responses'!$H$1:$H$200,8)) | I8: =IF($A8="","",COUNT(Matrix!$J$2:$J$351)) | J8: =IF($A8="","",COUNTIFS(Matrix!$J$2:$J$351,1,Matrix!$BA$2:$BA$351,1))
A9: =IF(INDEX('Form Responses'!$D$1:$D$200,9)="","",INDEX('Form Responses'!$D$1:$D$200,9)) | B9: =IF($A9="","",INDEX('Form Responses'!$C$1:$C$200,9)) | C9: =IF($A9="","",INDEX('Form Responses'!$E$1:$E$200,9)) | D9: =IF($A9="","",MIN(9,CEILING($C9/2,1))) | E9: =IF($A9="","",INDEX('Form Responses'!$F$1:$F$200,9)) | F9: =IF($A9="","",INDEX('Form Responses'!$G$1:$G$200,9)) | G9: =IF($A9="","",IF(ISNUMBER(SEARCH("Scribes",INDEX('Form Responses'!$G$1:$G$200,9))),"Yes","No")) | H9: =IF($A9="","",INDEX('Form Responses'!$H$1:$H$200,9)) | I9: =IF($A9="","",COUNT(Matrix!$K$2:$K$351)) | J9: =IF($A9="","",COUNTIFS(Matrix!$K$2:$K$351,1,Matrix!$BA$2:$BA$351,1))
A10: =IF(INDEX('Form Responses'!$D$1:$D$200,10)="","",INDEX('Form Responses'!$D$1:$D$200,10)) | B10: =IF($A10="","",INDEX('Form Responses'!$C$1:$C$200,10)) | C10: =IF($A10="","",INDEX('Form Responses'!$E$1:$E$200,10)) | D10: =IF($A10="","",MIN(9,CEILING($C10/2,1))) | E10: =IF($A10="","",INDEX('Form Responses'!$F$1:$F$200,10)) | F10: =IF($A10="","",INDEX('Form Responses'!$G$1:$G$200,10)) | G10: =IF($A10="","",IF(ISNUMBER(SEARCH("Scribes",INDEX('Form Responses'!$G$1:$G$200,10))),"Yes","No")) | H10: =IF($A10="","",INDEX('Form Responses'!$H$1:$H$200,10)) | I10: =IF($A10="","",COUNT(Matrix!$L$2:$L$351)) | J10: =IF($A10="","",COUNTIFS(Matrix!$L$2:$L$351,1,Matrix!$BA$2:$BA$351,1))
A11: =IF(INDEX('Form Responses'!$D$1:$D$200,11)="","",INDEX('Form Responses'!$D$1:$D$200,11)) | B11: =IF($A11="","",INDEX('Form Responses'!$C$1:$C$200,11)) | C11: =IF($A11="","",INDEX('Form Responses'!$E$1:$E$200,11)) | D11: =IF($A11="","",MIN(9,CEILING($C11/2,1))) | E11: =IF($A11="","",INDEX('Form Responses'!$F$1:$F$200,11)) | F11: =IF($A11="","",INDEX('Form Responses'!$G$1:$G$200,11)) | G11: =IF($A11="","",IF(ISNUMBER(SEARCH("Scribes",INDEX('Form Responses'!$G$1:$G$200,11))),"Yes","No")) | H11: =IF($A11="","",INDEX('Form Responses'!$H$1:$H$200,11)) | I11: =IF($A11="","",COUNT(Matrix!$M$2:$M$351)) | J11: =IF($A11="","",COUNTIFS(Matrix!$M$2:$M$351,1,Matrix!$BA$2:$BA$351,1))
A12: =IF(INDEX('Form Responses'!$D$1:$D$200,12)="","",INDEX('Form Responses'!$D$1:$D$200,12)) | B12: =IF($A12="","",INDEX('Form Responses'!$C$1:$C$200,12)) | C12: =IF($A12="","",INDEX('Form Responses'!$E$1:$E$200,12)) | D12: =IF($A12="","",MIN(9,CEILING($C12/2,1))) | E12: =IF($A12="","",INDEX('Form Responses'!$F$1:$F$200,12)) | F12: =IF($A12="","",INDEX('Form Responses'!$G$1:$G$200,12)) | G12: =IF($A12="","",IF(ISNUMBER(SEARCH("Scribes",INDEX('Form Responses'!$G$1:$G$200,12))),"Yes","No")) | H12: =IF($A12="","",INDEX('Form Responses'!$H$1:$H$200,12)) | I12: =IF($A12="","",COUNT(Matrix!$N$2:$N$351)) | J12: =IF($A12="","",COUNTIFS(Matrix!$N$2:$N$351,1,Matrix!$BA$2:$BA$351,1))
A13: =IF(INDEX('Form Responses'!$D$1:$D$200,13)="","",INDEX('Form Responses'!$D$1:$D$200,13)) | B13: =IF($A13="","",INDEX('Form Responses'!$C$1:$C$200,13)) | C13: =IF($A13="","",INDEX('Form Responses'!$E$1:$E$200,13)) | D13: =IF($A13="","",MIN(9,CEILING($C13/2,1))) | E13: =IF($A13="","",INDEX('Form Responses'!$F$1:$F$200,13)) | F13: =IF($A13="","",INDEX('Form Responses'!$G$1:$G$200,13)) | G13: =IF($A13="","",IF(ISNUMBER(SEARCH("Scribes",INDEX('Form Responses'!$G$1:$G$200,13))),"Yes","No")) | H13: =IF($A13="","",INDEX('Form Responses'!$H$1:$H$200,13)) | I13: =IF($A13="","",COUNT(Matrix!$O$2:$O$351)) | J13: =IF($A13="","",COUNTIFS(Matrix!$O$2:$O$351,1,Matrix!$BA$2:$BA$351,1))
A14: =IF(INDEX('Form Responses'!$D$1:$D$200,14)="","",INDEX('Form Responses'!$D$1:$D$200,14)) | B14: =IF($A14="","",INDEX('Form Responses'!$C$1:$C$200,14)) | C14: =IF($A14="","",INDEX('Form Responses'!$E$1:$E$200,14)) | D14: =IF($A14="","",MIN(9,CEILING($C14/2,1))) | E14: =IF($A14="","",INDEX('Form Responses'!$F$1:$F$200,14)) | F14: =IF($A14="","",INDEX('Form Responses'!$G$1:$G$200,14)) | G14: =IF($A14="","",IF(ISNUMBER(SEARCH("Scribes",INDEX('Form Responses'!$G$1:$G$200,14))),"Yes","No")) | H14: =IF($A14="","",INDEX('Form Responses'!$H$1:$H$200,14)) | I14: =IF($A14="","",COUNT(Matrix!$P$2:$P$351)) | J14: =IF($A14="","",COUNTIFS(Matrix!$P$2:$P$351,1,Matrix!$BA$2:$BA$351,1))
A15: =IF(INDEX('Form Responses'!$D$1:$D$200,15)="","",INDEX('Form Responses'!$D$1:$D$200,15)) | B15: =IF($A15="","",INDEX('Form Responses'!$C$1:$C$200,15)) | C15: =IF($A15="","",INDEX('Form Responses'!$E$1:$E$200,15)) | D15: =IF($A15="","",MIN(9,CEILING($C15/2,1))) | E15: =IF($A15="","",INDEX('Form Responses'!$F$1:$F$200,15)) | F15: =IF($A15="","",INDEX('Form Responses'!$G$1:$G$200,15)) | G15: =IF($A15="","",IF(ISNUMBER(SEARCH("Scribes",INDEX('Form Responses'!$G$1:$G$200,15))),"Yes","No")) | H15: =IF($A15="","",INDEX('Form Responses'!$H$1:$H$200,15)) | I15: =IF($A15="","",COUNT(Matrix!$Q$2:$Q$351)) | J15: =IF($A15="","",COUNTIFS(Matrix!$Q$2:$Q$351,1,Matrix!$BA$2:$BA$351,1))
A16: =IF(INDEX('Form Responses'!$D$1:$D$200,16)="","",INDEX('Form Responses'!$D$1:$D$200,16)) | B16: =IF($A16="","",INDEX('Form Responses'!$C$1:$C$200,16)) | C16: =IF($A16="","",INDEX('Form Responses'!$E$1:$E$200,16)) | D16: =IF($A16="","",MIN(9,CEILING($C16/2,1))) | E16: =IF($A16="","",INDEX('Form Responses'!$F$1:$F$200,16)) | F16: =IF($A16="","",INDEX('Form Responses'!$G$1:$G$200,16)) | G16: =IF($A16="","",IF(ISNUMBER(SEARCH("Scribes",INDEX('Form Responses'!$G$1:$G$200,16))),"Yes","No")) | H16: =IF($A16="","",INDEX('Form Responses'!$H$1:$H$200,16)) | I16: =IF($A16="","",COUNT(Matrix!$R$2:$R$351)) | J16: =IF($A16="","",COUNTIFS(Matrix!$R$2:$R$351,1,Matrix!$BA$2:$BA$351,1))
A17: =IF(INDEX('Form Responses'!$D$1:$D$200,17)="","",INDEX('Form Responses'!$D$1:$D$200,17)) | B17: =IF($A17="","",INDEX('Form Responses'!$C$1:$C$200,17)) | C17: =IF($A17="","",INDEX('Form Responses'!$E$1:$E$200,17)) | D17: =IF($A17="","",MIN(9,CEILING($C17/2,1))) | E17: =IF($A17="","",INDEX('Form Responses'!$F$1:$F$200,17)) | F17: =IF($A17="","",INDEX('Form Responses'!$G$1:$G$200,17)) | G17: =IF($A17="","",IF(ISNUMBER(SEARCH("Scribes",INDEX('Form Responses'!$G$1:$G$200,17))),"Yes","No")) | H17: =IF($A17="","",INDEX('Form Responses'!$H$1:$H$200,17)) | I17: =IF($A17="","",COUNT(Matrix!$S$2:$S$351)) | J17: =IF($A17="","",COUNTIFS(Matrix!$S$2:$S$351,1,Matrix!$BA$2:$BA$351,1))
A18: =IF(INDEX('Form Responses'!$D$1:$D$200,18)="","",INDEX('Form Responses'!$D$1:$D$200,18)) | B18: =IF($A18="","",INDEX('Form Responses'!$C$1:$C$200,18)) | C18: =IF($A18="","",INDEX('Form Responses'!$E$1:$E$200,18)) | D18: =IF($A18="","",MIN(9,CEILING($C18/2,1))) | E18: =IF($A18="","",INDEX('Form Responses'!$F$1:$F$200,18)) | F18: =IF($A18="","",INDEX('Form Responses'!$G$1:$G$200,18)) | G18: =IF($A18="","",IF(ISNUMBER(SEARCH("Scribes",INDEX('Form Responses'!$G$1:$G$200,18))),"Yes","No")) | H18: =IF($A18="","",INDEX('Form Responses'!$H$1:$H$200,18)) | I18: =IF($A18="","",COUNT(Matrix!$T$2:$T$351)) | J18: =IF($A18="","",COUNTIFS(Matrix!$T$2:$T$351,1,Matrix!$BA$2:$BA$351,1))
A19: =IF(INDEX('Form Responses'!$D$1:$D$200,19)="","",INDEX('Form Responses'!$D$1:$D$200,19)) | B19: =IF($A19="","",INDEX('Form Responses'!$C$1:$C$200,19)) | C19: =IF($A19="","",INDEX('Form Responses'!$E$1:$E$200,19)) | D19: =IF($A19="","",MIN(9,CEILING($C19/2,1))) | E19: =IF($A19="","",INDEX('Form Responses'!$F$1:$F$200,19)) | F19: =IF($A19="","",INDEX('Form Responses'!$G$1:$G$200,19)) | G19: =IF($A19="","",IF(ISNUMBER(SEARCH("Scribes",INDEX('Form Responses'!$G$1:$G$200,19))),"Yes","No")) | H19: =IF($A19="","",INDEX('Form Responses'!$H$1:$H$200,19)) | I19: =IF($A19="","",COUNT(Matrix!$U$2:$U$351)) | J19: =IF($A19="","",COUNTIFS(Matrix!$U$2:$U$351,1,Matrix!$BA$2:$BA$351,1))
A20: =IF(INDEX('Form Responses'!$D$1:$D$200,20)="","",INDEX('Form Responses'!$D$1:$D$200,20)) | B20: =IF($A20="","",INDEX('Form Responses'!$C$1:$C$200,20)) | C20: =IF($A20="","",INDEX('Form Responses'!$E$1:$E$200,20)) | D20: =IF($A20="","",MIN(9,CEILING($C20/2,1))) | E20: =IF($A20="","",INDEX('Form Responses'!$F$1:$F$200,20)) | F20: =IF($A20="","",INDEX('Form Responses'!$G$1:$G$200,20)) | G20: =IF($A20="","",IF(ISNUMBER(SEARCH("Scribes",INDEX('Form Responses'!$G$1:$G$200,20))),"Yes","No")) | H20: =IF($A20="","",INDEX('Form Responses'!$H$1:$H$200,20)) | I20: =IF($A20="","",COUNT(Matrix!$V$2:$V$351)) | J20: =IF($A20="","",COUNTIFS(Matrix!$V$2:$V$351,1,Matrix!$BA$2:$BA$351,1))
A21: =IF(INDEX('Form Responses'!$D$1:$D$200,21)="","",INDEX('Form Responses'!$D$1:$D$200,21)) | B21: =IF($A21="","",INDEX('Form Responses'!$C$1:$C$200,21)) | C21: =IF($A21="","",INDEX('Form Responses'!$E$1:$E$200,21)) | D21: =IF($A21="","",MIN(9,CEILING($C21/2,1))) | E21: =IF($A21="","",INDEX('Form Responses'!$F$1:$F$200,21)) | F21: =IF($A21="","",INDEX('Form Responses'!$G$1:$G$200,21)) | G21: =IF($A21="","",IF(ISNUMBER(SEARCH("Scribes",INDEX('Form Responses'!$G$1:$G$200,21))),"Yes","No")) | H21: =IF($A21="","",INDEX('Form Responses'!$H$1:$H$200,21)) | I21: =IF($A21="","",COUNT(Matrix!$W$2:$W$351)) | J21: =IF($A21="","",COUNTIFS(Matrix!$W$2:$W$351,1,Matrix!$BA$2:$BA$351,1))
A22: =IF(INDEX('Form Responses'!$D$1:$D$200,22)="","",INDEX('Form Responses'!$D$1:$D$200,22)) | B22: =IF($A22="","",INDEX('Form Responses'!$C$1:$C$200,22)) | C22: =IF($A22="","",INDEX('Form Responses'!$E$1:$E$200,22)) | D22: =IF($A22="","",MIN(9,CEILING($C22/2,1))) | E22: =IF($A22="","",INDEX('Form Responses'!$F$1:$F$200,22)) | F22: =IF($A22="","",INDEX('Form Responses'!$G$1:$G$200,22)) | G22: =IF($A22="","",IF(ISNUMBER(SEARCH("Scribes",INDEX('Form Responses'!$G$1:$G$200,22))),"Yes","No")) | H22: =IF($A22="","",INDEX('Form Responses'!$H$1:$H$200,22)) | I22: =IF($A22="","",COUNT(Matrix!$X$2:$X$351)) | J22: =IF($A22="","",COUNTIFS(Matrix!$X$2:$X$351,1,Matrix!$BA$2:$BA$351,1))
A23: =IF(INDEX('Form Responses'!$D$1:$D$200,23)="","",INDEX('Form Responses'!$D$1:$D$200,23)) | B23: =IF($A23="","",INDEX('Form Responses'!$C$1:$C$200,23)) | C23: =IF($A23="","",INDEX('Form Responses'!$E$1:$E$200,23)) | D23: =IF($A23="","",MIN(9,CEILING($C23/2,1))) | E23: =IF($A23="","",INDEX('Form Responses'!$F$1:$F$200,23)) | F23: =IF($A23="","",INDEX('Form Responses'!$G$1:$G$200,23)) | G23: =IF($A23="","",IF(ISNUMBER(SEARCH("Scribes",INDEX('Form Responses'!$G$1:$G$200,23))),"Yes","No")) | H23: =IF($A23="","",INDEX('Form Responses'!$H$1:$H$200,23)) | I23: =IF($A23="","",COUNT(Matrix!$Y$2:$Y$351)) | J23: =IF($A23="","",COUNTIFS(Matrix!$Y$2:$Y$351,1,Matrix!$BA$2:$BA$351,1))
A24: =IF(INDEX('Form Responses'!$D$1:$D$200,24)="","",INDEX('Form Responses'!$D$1:$D$200,24)) | B24: =IF($A24="","",INDEX('Form Responses'!$C$1:$C$200,24)) | C24: =IF($A24="","",INDEX('Form Responses'!$E$1:$E$200,24)) | D24: =IF($A24="","",MIN(9,CEILING($C24/2,1))) | E24: =IF($A24="","",INDEX('Form Responses'!$F$1:$F$200,24)) | F24: =IF($A24="","",INDEX('Form Responses'!$G$1:$G$200,24)) | G24: =IF($A24="","",IF(ISNUMBER(SEARCH("Scribes",INDEX('Form Responses'!$G$1:$G$200,24))),"Yes","No")) | H24: =IF($A24="","",INDEX('Form Responses'!$H$1:$H$200,24)) | I24: =IF($A24="","",COUNT(Matrix!$Z$2:$Z$351)) | J24: =IF($A24="","",COUNTIFS(Matrix!$Z$2:$Z$351,1,Matrix!$BA$2:$BA$351,1))
A25: =IF(INDEX('Form Responses'!$D$1:$D$200,25)="","",INDEX('Form Responses'!$D$1:$D$200,25)) | B25: =IF($A25="","",INDEX('Form Responses'!$C$1:$C$200,25)) | C25: =IF($A25="","",INDEX('Form Responses'!$E$1:$E$200,25)) | D25: =IF($A25="","",MIN(9,CEILING($C25/2,1))) | E25: =IF($A25="","",INDEX('Form Responses'!$F$1:$F$200,25)) | F25: =IF($A25="","",INDEX('Form Responses'!$G$1:$G$200,25)) | G25: =IF($A25="","",IF(ISNUMBER(SEARCH("Scribes",INDEX('Form Responses'!$G$1:$G$200,25))),"Yes","No")) | H25: =IF($A25="","",INDEX('Form Responses'!$H$1:$H$200,25)) | I25: =IF($A25="","",COUNT(Matrix!$AA$2:$AA$351)) | J25: =IF($A25="","",COUNTIFS(Matrix!$AA$2:$AA$351,1,Matrix!$BA$2:$BA$351,1))

Sheet Matrix
A1: Level | B1: Spell | C1: School | D1: =IF(Wizards!A2="","",Wizards!A2) | E1: =IF(Wizards!A3="","",Wizards!A3) | F1: =IF(Wizards!A4="","",Wizards!A4) | G1: =IF(Wizards!A5="","",Wizards!A5) | H1: =IF(Wizards!A6="","",Wizards!A6) | I1: =IF(Wizards!A7="","",Wizards!A7) | J1: =IF(Wizards!A8="","",Wizards!A8) | K1: =IF(Wizards!A9="","",Wizards!A9) | L1: =IF(Wizards!A10="","",Wizards!A10) | M1: =IF(Wizards!A11="","",Wizards!A11) | N1: =IF(Wizards!A12="","",Wizards!A12) | O1: =IF(Wizards!A13="","",Wizards!A13) | P1: =IF(Wizards!A14="","",Wizards!A14) | Q1: =IF(Wizards!A15="","",Wizards!A15) | R1: =IF(Wizards!A16="","",Wizards!A16) | S1: =IF(Wizards!A17="","",Wizards!A17) | T1: =IF(Wizards!A18="","",Wizards!A18) | U1: =IF(Wizards!A19="","",Wizards!A19) | V1: =IF(Wizards!A20="","",Wizards!A20) | W1: =IF(Wizards!A21="","",Wizards!A21) | X1: =IF(Wizards!A22="","",Wizards!A22) | Y1: =IF(Wizards!A23="","",Wizards!A23) | Z1: =IF(Wizards!A24="","",Wizards!A24) | AA1: =IF(Wizards!A25="","",Wizards!A25) | AB1: helper 1 | AC1: helper 2 | AD1: helper 3 | AE1: helper 4 | AF1: helper 5 | AG1: helper 6 | AH1: helper 7 | AI1: helper 8 | AJ1: helper 9 | AK1: helper 10 | AL1: helper 11 | AM1: helper 12 | AN1: helper 13 | AO1: helper 14 | AP1: helper 15 | AQ1: helper 16 | AR1: helper 17 | AS1: helper 18 | AT1: helper 19 | AU1: helper 20 | AV1: helper 21 | AW1: helper 22 | AX1: helper 23 | AY1: helper 24 | AZ1: Owners | BA1: # Owners
A2: 1 | B2: Absorb Elements | C2: Abjuration | D2: =IF(Wizards!$A$2="","",IF(OR(ISNUMBER(SEARCH(", "&$B2&", ", ", "&INDEX('Form Responses'!$I$1:$Q$200,2,$A2)&", ")),ISNUMBER(SEARCH(", "&$B2&", ", ", "&INDEX('Form Responses'!$R$1:$R$200,2)&", "))),1,"")) | E2: =IF(Wizards!$A$3="","",IF(OR(ISNUMBER(SEARCH(", "&$B2&", ", ", "&INDEX('Form Responses'!$I$1:$Q$200,3,$A2)&", ")),ISNUMBER(SEARCH(", "&$B2&", ", ", "&INDEX('Form Responses'!$R$1:$R$200,3)&", "))),1,"")) | F2: =IF(Wizards!$A$4="","",IF(OR(ISNUMBER(SEARCH(", "&$B2&", ", ", "&INDEX('Form Responses'!$I$1:$Q$200,4,$A2)&", ")),ISNUMBER(SEARCH(", "&$B2&", ", ", "&INDEX('Form Responses'!$R$1:$R$200,4)&", "))),1,"")) | G2: =IF(Wizards!$A$5="","",IF(OR(ISNUMBER(SEARCH(", "&$B2&", ", ", "&INDEX('Form Responses'!$I$1:$Q$200,5,$A2)&", ")),ISNUMBER(SEARCH(", "&$B2&", ", ", "&INDEX('Form Responses'!$R$1:$R$200,5)&", "))),1,"")) | H2: =IF(Wizards!$A$6="","",IF(OR(ISNUMBER(SEARCH(", "&$B2&", ", ", "&INDEX('Form Responses'!$I$1:$Q$200,6,$A2)&", ")),ISNUMBER(SEARCH(", "&$B2&", ", ", "&INDEX('Form Responses'!$R$1:$R$200,6)&", "))),1,"")) | I2: =IF(Wizards!$A$7="","",IF(OR(ISNUMBER(SEARCH(", "&$B2&", ", ", "&INDEX('Form Responses'!$I$1:$Q$200,7,$A2)&", ")),ISNUMBER(SEARCH(", "&$B2&", ", ", "&INDEX('Form Responses'!$R$1:$R$200,7)&", "))),1,"")) | J2: =IF(Wizards!$A$8="","",IF(OR(ISNUMBER(SEARCH(", "&$B2&", ", ", "&INDEX('Form Responses'!$I$1:$Q$200,8,$A2)&", ")),ISNUMBER(SEARCH(", "&$B2&", ", ", "&INDEX('Form Responses'!$R$1:$R$200,8)&", "))),1,"")) | K2: =IF(Wizards!$A$9="","",IF(OR(ISNUMBER(SEARCH(", "&$B2&", ", ", "&INDEX('Form Responses'!$I$1:$Q$200,9,$A2)&", ")),ISNUMBER(SEARCH(", "&$B2&", ", ", "&INDEX('Form Responses'!$R$1:$R$200,9)&", "))),1,"")) | L2: =IF(Wizards!$A$10="","",IF(OR(ISNUMBER(SEARCH(", "&$B2&", ", ", "&INDEX('Form Responses'!$I$1:$Q$200,10,$A2)&", ")),ISNUMBER(SEARCH(", "&$B2&", ", ", "&INDEX('Form Responses'!$R$1:$R$200,10)&", "))),1,"")) | M2: =IF(Wizards!$A$11="","",IF(OR(ISNUMBER(SEARCH(", "&$B2&", ", ", "&INDEX('Form Responses'!$I$1:$Q$200,11,$A2)&", ")),ISNUMBER(SEARCH(", "&$B2&", ", ", "&INDEX('Form Responses'!$R$1:$R$200,11)&", "))),1,"")) | N2: =IF(Wizards!$A$12="","",IF(OR(ISNUMBER(SEARCH(", "&$B2&", ", ", "&INDEX('Form Responses'!$I$1:$Q$200,12,$A2)&", ")),ISNUMBER(SEARCH(", "&$B2&", ", ", "&INDEX('Form Responses'!$R$1:$R$200,12)&", "))),1,"")) | O2: =IF(Wizards!$A$13="","",IF(OR(ISNUMBER(SEARCH(", "&$B2&", ", ", "&INDEX('Form Responses'!$I$1:$Q$200,13,$A2)&", ")),ISNUMBER(SEARCH(", "&$B2&", ", ", "&INDEX('Form Responses'!$R$1:$R$200,13)&", "))),1,"")) | P2: =IF(Wizards!$A$14="","",IF(OR(ISNUMBER(SEARCH(", "&$B2&", ", ", "&INDEX('Form Responses'!$I$1:$Q$200,14,$A2)&", ")),ISNUMBER(SEARCH(", "&$B2&", ", ", "&INDEX('Form Responses'!$R$1:$R$200,14)&", "))),1,"")) | Q2: =IF(Wizards!$A$15="","",IF(OR(ISNUMBER(SEARCH(", "&$B2&", ", ", "&INDEX('Form Responses'!$I$1:$Q$200,15,$A2)&", ")),ISNUMBER(SEARCH(", "&$B2&", ", ", "&INDEX('Form Responses'!$R$1:$R$200,15)&", "))),1,"")) | R2: =IF(Wizards!$A$16="","",IF(OR(ISNUMBER(SEARCH(", "&$B2&", ", ", "&INDEX('Form Responses'!$I$1:$Q$200,16,$A2)&", ")),ISNUMBER(SEARCH(", "&$B2&", ", ", "&INDEX('Form Responses'!$R$1:$R$200,16)&", "))),1,"")) | S2: =IF(Wizards!$A$17="","",IF(OR(ISNUMBER(SEARCH(", "&$B2&", ", ", "&INDEX('Form Responses'!$I$1:$Q$200,17,$A2)&", ")),ISNUMBER(SEARCH(", "&$B2&", ", ", "&INDEX('Form Responses'!$R$1:$R$200,17)&", "))),1,"")) | T2: =IF(Wizards!$A$18="","",IF(OR(ISNUMBER(SEARCH(", "&$B2&", ", ", "&INDEX('Form Responses'!$I$1:$Q$200,18,$A2)&", ")),ISNUMBER(SEARCH(", "&$B2&", ", ", "&INDEX('Form Responses'!$R$1:$R$200,18)&", "))),1,"")) | U2: =IF(Wizards!$A$19="","",IF(OR(ISNUMBER(SEARCH(", "&$B2&", ", ", "&INDEX('Form Responses'!$I$1:$Q$200,19,$A2)&", ")),ISNUMBER(SEARCH(", "&$B2&", ", ", "&INDEX('Form Responses'!$R$1:$R$200,19)&", "))),1,"")) | V2: =IF(Wizards!$A$20="","",IF(OR(ISNUMBER(SEARCH(", "&$B2&", ", ", "&INDEX('Form Responses'!$I$1:$Q$200,20,$A2)&", ")),ISNUMBER(SEARCH(", "&$B2&", ", ", "&INDEX('Form Responses'!$R$1:$R$200,20)&", "))),1,"")) | W2: =IF(Wizards!$A$21="","",IF(OR(ISNUMBER(SEARCH(", "&$B2&", ", ", "&INDEX('Form Responses'!$I$1:$Q$200,21,$A2)&", ")),ISNUMBER(SEARCH(", "&$B2&", ", ", "&INDEX('Form Responses'!$R$1:$R$200,21)&", "))),1,"")) | X2: =IF(Wizards!$A$22="","",IF(OR(ISNUMBER(SEARCH(", "&$B2&", ", ", "&INDEX('Form Responses'!$I$1:$Q$200,22,$A2)&", ")),ISNUMBER(SEARCH(", "&$B2&", ", ", "&INDEX('Form Responses'!$R$1:$R$200,22)&", "))),1,"")) | Y2: =IF(Wizards!$A$23="","",IF(OR(ISNUMBER(SEARCH(", "&$B2&", ", ", "&INDEX('Form Responses'!$I$1:$Q$200,23,$A2)&", ")),ISNUMBER(SEARCH(", "&$B2&", ", ", "&INDEX('Form Responses'!$R$1:$R$200,23)&", "))),1,"")) | Z2: =IF(Wizards!$A$24="","",IF(OR(ISNUMBER(SEARCH(", "&$B2&", ", ", "&INDEX('Form Responses'!$I$1:$Q$200,24,$A2)&", ")),ISNUMBER(SEARCH(", "&$B2&", ", ", "&INDEX('Form Responses'!$R$1:$R$200,24)&", "))),1,"")) | AA2: =IF(Wizards!$A$25="","",IF(OR(ISNUMBER(SEARCH(", "&$B2&", ", ", "&INDEX('Form Responses'!$I$1:$Q$200,25,$A2)&", ")),ISNUMBER(SEARCH(", "&$B2&", ", ", "&INDEX('Form Responses'!$R$1:$R$200,25)&", "))),1,"")) | AB2: =IF(D2=1,", "&D$1,"") | AC2: =IF(E2=1,", "&E$1,"") | AD2: =IF(F2=1,", "&F$1,"") | AE2: =IF(G2=1,", "&G$1,"") | AF2: =IF(H2=1,", "&H$1,"") | AG2: =IF(I2=1,", "&I$1,"") | AH2: =IF(J2=1,", "&J$1,"") | AI2: =IF(K2=1,", "&K$1,"") | ... AY2: =IF(AA2=1,", "&AA$1,"") | AZ2: =MID($AB2&$AC2&$AD2&$AE2&$AF2&$AG2&$AH2&$AI2&$AJ2&$AK2&$AL2&$AM2&$AN2&$AO2&$AP2&$AQ2&$AR2&$AS2&$AT2&$AU2&$AV2&$AW2&$AX2&$AY2,3,32767) | BA2: =COUNT($D2:$AA2)
A3: 1 | B3: Alarm | C3: Abjuration | D3: =IF(Wizards!$A$2="","",IF(OR(ISNUMBER(SEARCH(", "&$B3&", ", ", "&INDEX('Form Responses'!$I$1:$Q$200,2,$A3)&", ")),ISNUMBER(SEARCH(", "&$B3&", ", ", "&INDEX('Form Responses'!$R$1:$R$200,2)&", "))),1,"")) | E3: =IF(Wizards!$A$3="","",IF(OR(ISNUMBER(SEARCH(", "&$B3&", ", ", "&INDEX('Form Responses'!$I$1:$Q$200,3,$A3)&", ")),ISNUMBER(SEARCH(", "&$B3&", ", ", "&INDEX('Form Responses'!$R$1:$R$200,3)&", "))),1,"")) | F3: =IF(Wizards!$A$4="","",IF(OR(ISNUMBER(SEARCH(", "&$B3&", ", ", "&INDEX('Form Responses'!$I$1:$Q$200,4,$A3)&", ")),ISNUMBER(SEARCH(", "&$B3&", ", ", "&INDEX('Form Responses'!$R$1:$R$200,4)&", "))),1,"")) | G3: =IF(Wizards!$A$5="","",IF(OR(ISNUMBER(SEARCH(", "&$B3&", ", ", "&INDEX('Form Responses'!$I$1:$Q$200,5,$A3)&", ")),ISNUMBER(SEARCH(", "&$B3&", ", ", "&INDEX('Form Responses'!$R$1:$R$200,5)&", "))),1,"")) | H3: =IF(Wizards!$A$6="","",IF(OR(ISNUMBER(SEARCH(", "&$B3&", ", ", "&INDEX('Form Responses'!$I$1:$Q$200,6,$A3)&", ")),ISNUMBER(SEARCH(", "&$B3&", ", ", "&INDEX('Form Responses'!$R$1:$R$200,6)&", "))),1,"")) | I3: =IF(Wizards!$A$7="","",IF(OR(ISNUMBER(SEARCH(", "&$B3&", ", ", "&INDEX('Form Responses'!$I$1:$Q$200,7,$A3)&", ")),ISNUMBER(SEARCH(", "&$B3&", ", ", "&INDEX('Form Responses'!$R$1:$R$200,7)&", "))),1,"")) | J3: =IF(Wizards!$A$8="","",IF(OR(ISNUMBER(SEARCH(", "&$B3&", ", ", "&INDEX('Form Responses'!$I$1:$Q$200,8,$A3)&", ")),ISNUMBER(SEARCH(", "&$B3&", ", ", "&INDEX('Form Responses'!$R$1:$R$200,8)&", "))),1,"")) | K3: =IF(Wizards!$A$9="","",IF(OR(ISNUMBER(SEARCH(", "&$B3&", ", ", "&INDEX('Form Responses'!$I$1:$Q$200,9,$A3)&", ")),ISNUMBER(SEARCH(", "&$B3&", ", ", "&INDEX('Form Responses'!$R$1:$R$200,9)&", "))),1,"")) | L3: =IF(Wizards!$A$10="","",IF(OR(ISNUMBER(SEARCH(", "&$B3&", ", ", "&INDEX('Form Responses'!$I$1:$Q$200,10,$A3)&", ")),ISNUMBER(SEARCH(", "&$B3&", ", ", "&INDEX('Form Responses'!$R$1:$R$200,10)&", "))),1,"")) | M3: =IF(Wizards!$A$11="","",IF(OR(ISNUMBER(SEARCH(", "&$B3&", ", ", "&INDEX('Form Responses'!$I$1:$Q$200,11,$A3)&", ")),ISNUMBER(SEARCH(", "&$B3&", ", ", "&INDEX('Form Responses'!$R$1:$R$200,11)&", "))),1,"")) | N3: =IF(Wizards!$A$12="","",IF(OR(ISNUMBER(SEARCH(", "&$B3&", ", ", "&INDEX('Form Responses'!$I$1:$Q$200,12,$A3)&", ")),ISNUMBER(SEARCH(", "&$B3&", ", ", "&INDEX('Form Responses'!$R$1:$R$200,12)&", "))),1,"")) | O3: =IF(Wizards!$A$13="","",IF(OR(ISNUMBER(SEARCH(", "&$B3&", ", ", "&INDEX('Form Responses'!$I$1:$Q$200,13,$A3)&", ")),ISNUMBER(SEARCH(", "&$B3&", ", ", "&INDEX('Form Responses'!$R$1:$R$200,13)&", "))),1,"")) | P3: =IF(Wizards!$A$14="","",IF(OR(ISNUMBER(SEARCH(", "&$B3&", ", ", "&INDEX('Form Responses'!$I$1:$Q$200,14,$A3)&", ")),ISNUMBER(SEARCH(", "&$B3&", ", ", "&INDEX('Form Responses'!$R$1:$R$200,14)&", "))),1,"")) | Q3: =IF(Wizards!$A$15="","",IF(OR(ISNUMBER(SEARCH(", "&$B3&", ", ", "&INDEX('Form Responses'!$I$1:$Q$200,15,$A3)&", ")),ISNUMBER(SEARCH(", "&$B3&", ", ", "&INDEX('Form Responses'!$R$1:$R$200,15)&", "))),1,"")) | R3: =IF(Wizards!$A$16="","",IF(OR(ISNUMBER(SEARCH(", "&$B3&", ", ", "&INDEX('Form Responses'!$I$1:$Q$200,16,$A3)&", ")),ISNUMBER(SEARCH(", "&$B3&", ", ", "&INDEX('Form Responses'!$R$1:$R$200,16)&", "))),1,"")) | S3: =IF(Wizards!$A$17="","",IF(OR(ISNUMBER(SEARCH(", "&$B3&", ", ", "&INDEX('Form Responses'!$I$1:$Q$200,17,$A3)&", ")),ISNUMBER(SEARCH(", "&$B3&", ", ", "&INDEX('Form Responses'!$R$1:$R$200,17)&", "))),1,"")) | T3: =IF(Wizards!$A$18="","",IF(OR(ISNUMBER(SEARCH(", "&$B3&", ", ", "&INDEX('Form Responses'!$I$1:$Q$200,18,$A3)&", ")),ISNUMBER(SEARCH(", "&$B3&", ", ", "&INDEX('Form Responses'!$R$1:$R$200,18)&", "))),1,"")) | U3: =IF(Wizards!$A$19="","",IF(OR(ISNUMBER(SEARCH(", "&$B3&", ", ", "&INDEX('Form Responses'!$I$1:$Q$200,19,$A3)&", ")),ISNUMBER(SEARCH(", "&$B3&", ", ", "&INDEX('Form Responses'!$R$1:$R$200,19)&", "))),1,"")) | V3: =IF(Wizards!$A$20="","",IF(OR(ISNUMBER(SEARCH(", "&$B3&", ", ", "&INDEX('Form Responses'!$I$1:$Q$200,20,$A3)&", ")),ISNUMBER(SEARCH(", "&$B3&", ", ", "&INDEX('Form Responses'!$R$1:$R$200,20)&", "))),1,"")) | W3: =IF(Wizards!$A$21="","",IF(OR(ISNUMBER(SEARCH(", "&$B3&", ", ", "&INDEX('Form Responses'!$I$1:$Q$200,21,$A3)&", ")),ISNUMBER(SEARCH(", "&$B3&", ", ", "&INDEX('Form Responses'!$R$1:$R$200,21)&", "))),1,"")) | X3: =IF(Wizards!$A$22="","",IF(OR(ISNUMBER(SEARCH(", "&$B3&", ", ", "&INDEX('Form Responses'!$I$1:$Q$200,22,$A3)&", ")),ISNUMBER(SEARCH(", "&$B3&", ", ", "&INDEX('Form Responses'!$R$1:$R$200,22)&", "))),1,"")) | Y3: =IF(Wizards!$A$23="","",IF(OR(ISNUMBER(SEARCH(", "&$B3&", ", ", "&INDEX('Form Responses'!$I$1:$Q$200,23,$A3)&", ")),ISNUMBER(SEARCH(", "&$B3&", ", ", "&INDEX('Form Responses'!$R$1:$R$200,23)&", "))),1,"")) | Z3: =IF(Wizards!$A$24="","",IF(OR(ISNUMBER(SEARCH(", "&$B3&", ", ", "&INDEX('Form Responses'!$I$1:$Q$200,24,$A3)&", ")),ISNUMBER(SEARCH(", "&$B3&", ", ", "&INDEX('Form Responses'!$R$1:$R$200,24)&", "))),1,"")) | AA3: =IF(Wizards!$A$25="","",IF(OR(ISNUMBER(SEARCH(", "&$B3&", ", ", "&INDEX('Form Responses'!$I$1:$Q$200,25,$A3)&", ")),ISNUMBER(SEARCH(", "&$B3&", ", ", "&INDEX('Form Responses'!$R$1:$R$200,25)&", "))),1,"")) | AB3: =IF(D3=1,", "&D$1,"") | AC3: =IF(E3=1,", "&E$1,"") | AD3: =IF(F3=1,", "&F$1,"") | AE3: =IF(G3=1,", "&G$1,"") | AF3: =IF(H3=1,", "&H$1,"") | AG3: =IF(I3=1,", "&I$1,"") | AH3: =IF(J3=1,", "&J$1,"") | AI3: =IF(K3=1,", "&K$1,"") | ... AY3: =IF(AA3=1,", "&AA$1,"") | AZ3: =MID($AB3&$AC3&$AD3&$AE3&$AF3&$AG3&$AH3&$AI3&$AJ3&$AK3&$AL3&$AM3&$AN3&$AO3&$AP3&$AQ3&$AR3&$AS3&$AT3&$AU3&$AV3&$AW3&$AX3&$AY3,3,32767) | BA3: =COUNT($D3:$AA3)
A4: 1 | B4: Burning Hands | C4: Evocation | D4: =IF(Wizards!$A$2="","",IF(OR(ISNUMBER(SEARCH(", "&$B4&", ", ", "&INDEX('Form Responses'!$I$1:$Q$200,2,$A4)&", ")),ISNUMBER(SEARCH(", "&$B4&", ", ", "&INDEX('Form Responses'!$R$1:$R$200,2)&", "))),1,"")) | E4: =IF(Wizards!$A$3="","",IF(OR(ISNUMBER(SEARCH(", "&$B4&", ", ", "&INDEX('Form Responses'!$I$1:$Q$200,3,$A4)&", ")),ISNUMBER(SEARCH(", "&$B4&", ", ", "&INDEX('Form Responses'!$R$1:$R$200,3)&", "))),1,"")) | F4: =IF(Wizards!$A$4="","",IF(OR(ISNUMBER(SEARCH(", "&$B4&", ", ", "&INDEX('Form Responses'!$I$1:$Q$200,4,$A4)&", ")),ISNUMBER(SEARCH(", "&$B4&", ", ", "&INDEX('Form Responses'!$R$1:$R$200,4)&", "))),1,"")) | G4: =IF(Wizards!$A$5="","",IF(OR(ISNUMBER(SEARCH(", "&$B4&", ", ", "&INDEX('Form Responses'!$I$1:$Q$200,5,$A4)&", ")),ISNUMBER(SEARCH(", "&$B4&", ", ", "&INDEX('Form Responses'!$R$1:$R$200,5)&", "))),1,"")) | H4: =IF(Wizards!$A$6="","",IF(OR(ISNUMBER(SEARCH(", "&$B4&", ", ", "&INDEX('Form Responses'!$I$1:$Q$200,6,$A4)&", ")),ISNUMBER(SEARCH(", "&$B4&", ", ", "&INDEX('Form Responses'!$R$1:$R$200,6)&", "))),1,"")) | I4: =IF(Wizards!$A$7="","",IF(OR(ISNUMBER(SEARCH(", "&$B4&", ", ", "&INDEX('Form Responses'!$I$1:$Q$200,7,$A4)&", ")),ISNUMBER(SEARCH(", "&$B4&", ", ", "&INDEX('Form Responses'!$R$1:$R$200,7)&", "))),1,"")) | J4: =IF(Wizards!$A$8="","",IF(OR(ISNUMBER(SEARCH(", "&$B4&", ", ", "&INDEX('Form Responses'!$I$1:$Q$200,8,$A4)&", ")),ISNUMBER(SEARCH(", "&$B4&", ", ", "&INDEX('Form Responses'!$R$1:$R$200,8)&", "))),1,"")) | K4: =IF(Wizards!$A$9="","",IF(OR(ISNUMBER(SEARCH(", "&$B4&", ", ", "&INDEX('Form Responses'!$I$1:$Q$200,9,$A4)&", ")),ISNUMBER(SEARCH(", "&$B4&", ", ", "&INDEX('Form Responses'!$R$1:$R$200,9)&", "))),1,"")) | L4: =IF(Wizards!$A$10="","",IF(OR(ISNUMBER(SEARCH(", "&$B4&", ", ", "&INDEX('Form Responses'!$I$1:$Q$200,10,$A4)&", ")),ISNUMBER(SEARCH(", "&$B4&", ", ", "&INDEX('Form Responses'!$R$1:$R$200,10)&", "))),1,"")) | M4: =IF(Wizards!$A$11="","",IF(OR(ISNUMBER(SEARCH(", "&$B4&", ", ", "&INDEX('Form Responses'!$I$1:$Q$200,11,$A4)&", ")),ISNUMBER(SEARCH(", "&$B4&", ", ", "&INDEX('Form Responses'!$R$1:$R$200,11)&", "))),1,"")) | N4: =IF(Wizards!$A$12="","",IF(OR(ISNUMBER(SEARCH(", "&$B4&", ", ", "&INDEX('Form Responses'!$I$1:$Q$200,12,$A4)&", ")),ISNUMBER(SEARCH(", "&$B4&", ", ", "&INDEX('Form Responses'!$R$1:$R$200,12)&", "))),1,"")) | O4: =IF(Wizards!$A$13="","",IF(OR(ISNUMBER(SEARCH(", "&$B4&", ", ", "&INDEX('Form Responses'!$I$1:$Q$200,13,$A4)&", ")),ISNUMBER(SEARCH(", "&$B4&", ", ", "&INDEX('Form Responses'!$R$1:$R$200,13)&", "))),1,"")) | P4: =IF(Wizards!$A$14="","",IF(OR(ISNUMBER(SEARCH(", "&$B4&", ", ", "&INDEX('Form Responses'!$I$1:$Q$200,14,$A4)&", ")),ISNUMBER(SEARCH(", "&$B4&", ", ", "&INDEX('Form Responses'!$R$1:$R$200,14)&", "))),1,"")) | Q4: =IF(Wizards!$A$15="","",IF(OR(ISNUMBER(SEARCH(", "&$B4&", ", ", "&INDEX('Form Responses'!$I$1:$Q$200,15,$A4)&", ")),ISNUMBER(SEARCH(", "&$B4&", ", ", "&INDEX('Form Responses'!$R$1:$R$200,15)&", "))),1,"")) | R4: =IF(Wizards!$A$16="","",IF(OR(ISNUMBER(SEARCH(", "&$B4&", ", ", "&INDEX('Form Responses'!$I$1:$Q$200,16,$A4)&", ")),ISNUMBER(SEARCH(", "&$B4&", ", ", "&INDEX('Form Responses'!$R$1:$R$200,16)&", "))),1,"")) | S4: =IF(Wizards!$A$17="","",IF(OR(ISNUMBER(SEARCH(", "&$B4&", ", ", "&INDEX('Form Responses'!$I$1:$Q$200,17,$A4)&", ")),ISNUMBER(SEARCH(", "&$B4&", ", ", "&INDEX('Form Responses'!$R$1:$R$200,17)&", "))),1,"")) | T4: =IF(Wizards!$A$18="","",IF(OR(ISNUMBER(SEARCH(", "&$B4&", ", ", "&INDEX('Form Responses'!$I$1:$Q$200,18,$A4)&", ")),ISNUMBER(SEARCH(", "&$B4&", ", ", "&INDEX('Form Responses'!$R$1:$R$200,18)&", "))),1,"")) | U4: =IF(Wizards!$A$19="","",IF(OR(ISNUMBER(SEARCH(", "&$B4&", ", ", "&INDEX('Form Responses'!$I$1:$Q$200,19,$A4)&", ")),ISNUMBER(SEARCH(", "&$B4&", ", ", "&INDEX('Form Responses'!$R$1:$R$200,19)&", "))),1,"")) | V4: =IF(Wizards!$A$20="","",IF(OR(ISNUMBER(SEARCH(", "&$B4&", ", ", "&INDEX('Form Responses'!$I$1:$Q$200,20,$A4)&", ")),ISNUMBER(SEARCH(", "&$B4&", ", ", "&INDEX('Form Responses'!$R$1:$R$200,20)&", "))),1,"")) | W4: =IF(Wizards!$A$21="","",IF(OR(ISNUMBER(SEARCH(", "&$B4&", ", ", "&INDEX('Form Responses'!$I$1:$Q$200,21,$A4)&", ")),ISNUMBER(SEARCH(", "&$B4&", ", ", "&INDEX('Form Responses'!$R$1:$R$200,21)&", "))),1,"")) | X4: =IF(Wizards!$A$22="","",IF(OR(ISNUMBER(SEARCH(", "&$B4&", ", ", "&INDEX('Form Responses'!$I$1:$Q$200,22,$A4)&", ")),ISNUMBER(SEARCH(", "&$B4&", ", ", "&INDEX('Form Responses'!$R$1:$R$200,22)&", "))),1,"")) | Y4: =IF(Wizards!$A$23="","",IF(OR(ISNUMBER(SEARCH(", "&$B4&", ", ", "&INDEX('Form Responses'!$I$1:$Q$200,23,$A4)&", ")),ISNUMBER(SEARCH(", "&$B4&", ", ", "&INDEX('Form Responses'!$R$1:$R$200,23)&", "))),1,"")) | Z4: =IF(Wizards!$A$24="","",IF(OR(ISNUMBER(SEARCH(", "&$B4&", ", ", "&INDEX('Form Responses'!$I$1:$Q$200,24,$A4)&", ")),ISNUMBER(SEARCH(", "&$B4&", ", ", "&INDEX('Form Responses'!$R$1:$R$200,24)&", "))),1,"")) | AA4: =IF(Wizards!$A$25="","",IF(OR(ISNUMBER(SEARCH(", "&$B4&", ", ", "&INDEX('Form Responses'!$I$1:$Q$200,25,$A4)&", ")),ISNUMBER(SEARCH(", "&$B4&", ", ", "&INDEX('Form Responses'!$R$1:$R$200,25)&", "))),1,"")) | AB4: =IF(D4=1,", "&D$1,"") | AC4: =IF(E4=1,", "&E$1,"") | AD4: =IF(F4=1,", "&F$1,"") | AE4: =IF(G4=1,", "&G$1,"") | AF4: =IF(H4=1,", "&H$1,"") | AG4: =IF(I4=1,", "&I$1,"") | AH4: =IF(J4=1,", "&J$1,"") | AI4: =IF(K4=1,", "&K$1,"") | ... AY4: =IF(AA4=1,", "&AA$1,"") | AZ4: =MID($AB4&$AC4&$AD4&$AE4&$AF4&$AG4&$AH4&$AI4&$AJ4&$AK4&$AL4&$AM4&$AN4&$AO4&$AP4&$AQ4&$AR4&$AS4&$AT4&$AU4&$AV4&$AW4&$AX4&$AY4,3,32767) | BA4: =COUNT($D4:$AA4)
A5: 1 | B5: Catapult | C5: Transmutation | D5: =IF(Wizards!$A$2="","",IF(OR(ISNUMBER(SEARCH(", "&$B5&", ", ", "&INDEX('Form Responses'!$I$1:$Q$200,2,$A5)&", ")),ISNUMBER(SEARCH(", "&$B5&", ", ", "&INDEX('Form Responses'!$R$1:$R$200,2)&", "))),1,"")) | E5: =IF(Wizards!$A$3="","",IF(OR(ISNUMBER(SEARCH(", "&$B5&", ", ", "&INDEX('Form Responses'!$I$1:$Q$200,3,$A5)&", ")),ISNUMBER(SEARCH(", "&$B5&", ", ", "&INDEX('Form Responses'!$R$1:$R$200,3)&", "))),1,"")) | F5: =IF(Wizards!$A$4="","",IF(OR(ISNUMBER(SEARCH(", "&$B5&", ", ", "&INDEX('Form Responses'!$I$1:$Q$200,4,$A5)&", ")),ISNUMBER(SEARCH(", "&$B5&", ", ", "&INDEX('Form Responses'!$R$1:$R$200,4)&", "))),1,"")) | G5: =IF(Wizards!$A$5="","",IF(OR(ISNUMBER(SEARCH(", "&$B5&", ", ", "&INDEX('Form Responses'!$I$1:$Q$200,5,$A5)&", ")),ISNUMBER(SEARCH(", "&$B5&", ", ", "&INDEX('Form Responses'!$R$1:$R$200,5)&", "))),1,"")) | H5: =IF(Wizards!$A$6="","",IF(OR(ISNUMBER(SEARCH(", "&$B5&", ", ", "&INDEX('Form Responses'!$I$1:$Q$200,6,$A5)&", ")),ISNUMBER(SEARCH(", "&$B5&", ", ", "&INDEX('Form Responses'!$R$1:$R$200,6)&", "))),1,"")) | I5: =IF(Wizards!$A$7="","",IF(OR(ISNUMBER(SEARCH(", "&$B5&", ", ", "&INDEX('Form Responses'!$I$1:$Q$200,7,$A5)&", ")),ISNUMBER(SEARCH(", "&$B5&", ", ", "&INDEX('Form Responses'!$R$1:$R$200,7)&", "))),1,"")) | J5: =IF(Wizards!$A$8="","",IF(OR(ISNUMBER(SEARCH(", "&$B5&", ", ", "&INDEX('Form Responses'!$I$1:$Q$200,8,$A5)&", ")),ISNUMBER(SEARCH(", "&$B5&", ", ", "&INDEX('Form Responses'!$R$1:$R$200,8)&", "))),1,"")) | K5: =IF(Wizards!$A$9="","",IF(OR(ISNUMBER(SEARCH(", "&$B5&", ", ", "&INDEX('Form Responses'!$I$1:$Q$200,9,$A5)&", ")),ISNUMBER(SEARCH(", "&$B5&", ", ", "&INDEX('Form Responses'!$R$1:$R$200,9)&", "))),1,"")) | L5: =IF(Wizards!$A$10="","",IF(OR(ISNUMBER(SEARCH(", "&$B5&", ", ", "&INDEX('Form Responses'!$I$1:$Q$200,10,$A5)&", ")),ISNUMBER(SEARCH(", "&$B5&", ", ", "&INDEX('Form Responses'!$R$1:$R$200,10)&", "))),1,"")) | M5: =IF(Wizards!$A$11="","",IF(OR(ISNUMBER(SEARCH(", "&$B5&", ", ", "&INDEX('Form Responses'!$I$1:$Q$200,11,$A5)&", ")),ISNUMBER(SEARCH(", "&$B5&", ", ", "&INDEX('Form Responses'!$R$1:$R$200,11)&", "))),1,"")) | N5: =IF(Wizards!$A$12="","",IF(OR(ISNUMBER(SEARCH(", "&$B5&", ", ", "&INDEX('Form Responses'!$I$1:$Q$200,12,$A5)&", ")),ISNUMBER(SEARCH(", "&$B5&", ", ", "&INDEX('Form Responses'!$R$1:$R$200,12)&", "))),1,"")) | O5: =IF(Wizards!$A$13="","",IF(OR(ISNUMBER(SEARCH(", "&$B5&", ", ", "&INDEX('Form Responses'!$I$1:$Q$200,13,$A5)&", ")),ISNUMBER(SEARCH(", "&$B5&", ", ", "&INDEX('Form Responses'!$R$1:$R$200,13)&", "))),1,"")) | P5: =IF(Wizards!$A$14="","",IF(OR(ISNUMBER(SEARCH(", "&$B5&", ", ", "&INDEX('Form Responses'!$I$1:$Q$200,14,$A5)&", ")),ISNUMBER(SEARCH(", "&$B5&", ", ", "&INDEX('Form Responses'!$R$1:$R$200,14)&", "))),1,"")) | Q5: =IF(Wizards!$A$15="","",IF(OR(ISNUMBER(SEARCH(", "&$B5&", ", ", "&INDEX('Form Responses'!$I$1:$Q$200,15,$A5)&", ")),ISNUMBER(SEARCH(", "&$B5&", ", ", "&INDEX('Form Responses'!$R$1:$R$200,15)&", "))),1,"")) | R5: =IF(Wizards!$A$16="","",IF(OR(ISNUMBER(SEARCH(", "&$B5&", ", ", "&INDEX('Form Responses'!$I$1:$Q$200,16,$A5)&", ")),ISNUMBER(SEARCH(", "&$B5&", ", ", "&INDEX('Form Responses'!$R$1:$R$200,16)&", "))),1,"")) | S5: =IF(Wizards!$A$17="","",IF(OR(ISNUMBER(SEARCH(", "&$B5&", ", ", "&INDEX('Form Responses'!$I$1:$Q$200,17,$A5)&", ")),ISNUMBER(SEARCH(", "&$B5&", ", ", "&INDEX('Form Responses'!$R$1:$R$200,17)&", "))),1,"")) | T5: =IF(Wizards!$A$18="","",IF(OR(ISNUMBER(SEARCH(", "&$B5&", ", ", "&INDEX('Form Responses'!$I$1:$Q$200,18,$A5)&", ")),ISNUMBER(SEARCH(", "&$B5&", ", ", "&INDEX('Form Responses'!$R$1:$R$200,18)&", "))),1,"")) | U5: =IF(Wizards!$A$19="","",IF(OR(ISNUMBER(SEARCH(", "&$B5&", ", ", "&INDEX('Form Responses'!$I$1:$Q$200,19,$A5)&", ")),ISNUMBER(SEARCH(", "&$B5&", ", ", "&INDEX('Form Responses'!$R$1:$R$200,19)&", "))),1,"")) | V5: =IF(Wizards!$A$20="","",IF(OR(ISNUMBER(SEARCH(", "&$B5&", ", ", "&INDEX('Form Responses'!$I$1:$Q$200,20,$A5)&", ")),ISNUMBER(SEARCH(", "&$B5&", ", ", "&INDEX('Form Responses'!$R$1:$R$200,20)&", "))),1,"")) | W5: =IF(Wizards!$A$21="","",IF(OR(ISNUMBER(SEARCH(", "&$B5&", ", ", "&INDEX('Form Responses'!$I$1:$Q$200,21,$A5)&", ")),ISNUMBER(SEARCH(", "&$B5&", ", ", "&INDEX('Form Responses'!$R$1:$R$200,21)&", "))),1,"")) | X5: =IF(Wizards!$A$22="","",IF(OR(ISNUMBER(SEARCH(", "&$B5&", ", ", "&INDEX('Form Responses'!$I$1:$Q$200,22,$A5)&", ")),ISNUMBER(SEARCH(", "&$B5&", ", ", "&INDEX('Form Responses'!$R$1:$R$200,22)&", "))),1,"")) | Y5: =IF(Wizards!$A$23="","",IF(OR(ISNUMBER(SEARCH(", "&$B5&", ", ", "&INDEX('Form Responses'!$I$1:$Q$200,23,$A5)&", ")),ISNUMBER(SEARCH(", "&$B5&", ", ", "&INDEX('Form Responses'!$R$1:$R$200,23)&", "))),1,"")) | Z5: =IF(Wizards!$A$24="","",IF(OR(ISNUMBER(SEARCH(", "&$B5&", ", ", "&INDEX('Form Responses'!$I$1:$Q$200,24,$A5)&", ")),ISNUMBER(SEARCH(", "&$B5&", ", ", "&INDEX('Form Responses'!$R$1:$R$200,24)&", "))),1,"")) | AA5: =IF(Wizards!$A$25="","",IF(OR(ISNUMBER(SEARCH(", "&$B5&", ", ", "&INDEX('Form Responses'!$I$1:$Q$200,25,$A5)&", ")),ISNUMBER(SEARCH(", "&$B5&", ", ", "&INDEX('Form Responses'!$R$1:$R$200,25)&", "))),1,"")) | AB5: =IF(D5=1,", "&D$1,"") | AC5: =IF(E5=1,", "&E$1,"") | AD5: =IF(F5=1,", "&F$1,"") | AE5: =IF(G5=1,", "&G$1,"") | AF5: =IF(H5=1,", "&H$1,"") | AG5: =IF(I5=1,", "&I$1,"") | AH5: =IF(J5=1,", "&J$1,"") | AI5: =IF(K5=1,", "&K$1,"") | ... AY5: =IF(AA5=1,", "&AA$1,"") | AZ5: =MID($AB5&$AC5&$AD5&$AE5&$AF5&$AG5&$AH5&$AI5&$AJ5&$AK5&$AL5&$AM5&$AN5&$AO5&$AP5&$AQ5&$AR5&$AS5&$AT5&$AU5&$AV5&$AW5&$AX5&$AY5,3,32767) | BA5: =COUNT($D5:$AA5)
A6: 1 | B6: Cause Fear | C6: Necromancy | D6: =IF(Wizards!$A$2="","",IF(OR(ISNUMBER(SEARCH(", "&$B6&", ", ", "&INDEX('Form Responses'!$I$1:$Q$200,2,$A6)&", ")),ISNUMBER(SEARCH(", "&$B6&", ", ", "&INDEX('Form Responses'!$R$1:$R$200,2)&", "))),1,"")) | E6: =IF(Wizards!$A$3="","",IF(OR(ISNUMBER(SEARCH(", "&$B6&", ", ", "&INDEX('Form Responses'!$I$1:$Q$200,3,$A6)&", ")),ISNUMBER(SEARCH(", "&$B6&", ", ", "&INDEX('Form Responses'!$R$1:$R$200,3)&", "))),1,"")) | F6: =IF(Wizards!$A$4="","",IF(OR(ISNUMBER(SEARCH(", "&$B6&", ", ", "&INDEX('Form Responses'!$I$1:$Q$200,4,$A6)&", ")),ISNUMBER(SEARCH(", "&$B6&", ", ", "&INDEX('Form Responses'!$R$1:$R$200,4)&", "))),1,"")) | G6: =IF(Wizards!$A$5="","",IF(OR(ISNUMBER(SEARCH(", "&$B6&", ", ", "&INDEX('Form Responses'!$I$1:$Q$200,5,$A6)&", ")),ISNUMBER(SEARCH(", "&$B6&", ", ", "&INDEX('Form Responses'!$R$1:$R$200,5)&", "))),1,"")) | H6: =IF(Wizards!$A$6="","",IF(OR(ISNUMBER(SEARCH(", "&$B6&", ", ", "&INDEX('Form Responses'!$I$1:$Q$200,6,$A6)&", ")),ISNUMBER(SEARCH(", "&$B6&", ", ", "&INDEX('Form Responses'!$R$1:$R$200,6)&", "))),1,"")) | I6: =IF(Wizards!$A$7="","",IF(OR(ISNUMBER(SEARCH(", "&$B6&", ", ", "&INDEX('Form Responses'!$I$1:$Q$200,7,$A6)&", ")),ISNUMBER(SEARCH(", "&$B6&", ", ", "&INDEX('Form Responses'!$R$1:$R$200,7)&", "))),1,"")) | J6: =IF(Wizards!$A$8="","",IF(OR(ISNUMBER(SEARCH(", "&$B6&", ", ", "&INDEX('Form Responses'!$I$1:$Q$200,8,$A6)&", ")),ISNUMBER(SEARCH(", "&$B6&", ", ", "&INDEX('Form Responses'!$R$1:$R$200,8)&", "))),1,"")) | K6: =IF(Wizards!$A$9="","",IF(OR(ISNUMBER(SEARCH(", "&$B6&", ", ", "&INDEX('Form Responses'!$I$1:$Q$200,9,$A6)&", ")),ISNUMBER(SEARCH(", "&$B6&", ", ", "&INDEX('Form Responses'!$R$1:$R$200,9)&", "))),1,"")) | L6: =IF(Wizards!$A$10="","",IF(OR(ISNUMBER(SEARCH(", "&$B6&", ", ", "&INDEX('Form Responses'!$I$1:$Q$200,10,$A6)&", ")),ISNUMBER(SEARCH(", "&$B6&", ", ", "&INDEX('Form Responses'!$R$1:$R$200,10)&", "))),1,"")) | M6: =IF(Wizards!$A$11="","",IF(OR(ISNUMBER(SEARCH(", "&$B6&", ", ", "&INDEX('Form Responses'!$I$1:$Q$200,11,$A6)&", ")),ISNUMBER(SEARCH(", "&$B6&", ", ", "&INDEX('Form Responses'!$R$1:$R$200,11)&", "))),1,"")) | N6: =IF(Wizards!$A$12="","",IF(OR(ISNUMBER(SEARCH(", "&$B6&", ", ", "&INDEX('Form Responses'!$I$1:$Q$200,12,$A6)&", ")),ISNUMBER(SEARCH(", "&$B6&", ", ", "&INDEX('Form Responses'!$R$1:$R$200,12)&", "))),1,"")) | O6: =IF(Wizards!$A$13="","",IF(OR(ISNUMBER(SEARCH(", "&$B6&", ", ", "&INDEX('Form Responses'!$I$1:$Q$200,13,$A6)&", ")),ISNUMBER(SEARCH(", "&$B6&", ", ", "&INDEX('Form Responses'!$R$1:$R$200,13)&", "))),1,"")) | P6: =IF(Wizards!$A$14="","",IF(OR(ISNUMBER(SEARCH(", "&$B6&", ", ", "&INDEX('Form Responses'!$I$1:$Q$200,14,$A6)&", ")),ISNUMBER(SEARCH(", "&$B6&", ", ", "&INDEX('Form Responses'!$R$1:$R$200,14)&", "))),1,"")) | Q6: =IF(Wizards!$A$15="","",IF(OR(ISNUMBER(SEARCH(", "&$B6&", ", ", "&INDEX('Form Responses'!$I$1:$Q$200,15,$A6)&", ")),ISNUMBER(SEARCH(", "&$B6&", ", ", "&INDEX('Form Responses'!$R$1:$R$200,15)&", "))),1,"")) | R6: =IF(Wizards!$A$16="","",IF(OR(ISNUMBER(SEARCH(", "&$B6&", ", ", "&INDEX('Form Responses'!$I$1:$Q$200,16,$A6)&", ")),ISNUMBER(SEARCH(", "&$B6&", ", ", "&INDEX('Form Responses'!$R$1:$R$200,16)&", "))),1,"")) | S6: =IF(Wizards!$A$17="","",IF(OR(ISNUMBER(SEARCH(", "&$B6&", ", ", "&INDEX('Form Responses'!$I$1:$Q$200,17,$A6)&", ")),ISNUMBER(SEARCH(", "&$B6&", ", ", "&INDEX('Form Responses'!$R$1:$R$200,17)&", "))),1,"")) | T6: =IF(Wizards!$A$18="","",IF(OR(ISNUMBER(SEARCH(", "&$B6&", ", ", "&INDEX('Form Responses'!$I$1:$Q$200,18,$A6)&", ")),ISNUMBER(SEARCH(", "&$B6&", ", ", "&INDEX('Form Responses'!$R$1:$R$200,18)&", "))),1,"")) | U6: =IF(Wizards!$A$19="","",IF(OR(ISNUMBER(SEARCH(", "&$B6&", ", ", "&INDEX('Form Responses'!$I$1:$Q$200,19,$A6)&", ")),ISNUMBER(SEARCH(", "&$B6&", ", ", "&INDEX('Form Responses'!$R$1:$R$200,19)&", "))),1,"")) | V6: =IF(Wizards!$A$20="","",IF(OR(ISNUMBER(SEARCH(", "&$B6&", ", ", "&INDEX('Form Responses'!$I$1:$Q$200,20,$A6)&", ")),ISNUMBER(SEARCH(", "&$B6&", ", ", "&INDEX('Form Responses'!$R$1:$R$200,20)&", "))),1,"")) | W6: =IF(Wizards!$A$21="","",IF(OR(ISNUMBER(SEARCH(", "&$B6&", ", ", "&INDEX('Form Responses'!$I$1:$Q$200,21,$A6)&", ")),ISNUMBER(SEARCH(", "&$B6&", ", ", "&INDEX('Form Responses'!$R$1:$R$200,21)&", "))),1,"")) | X6: =IF(Wizards!$A$22="","",IF(OR(ISNUMBER(SEARCH(", "&$B6&", ", ", "&INDEX('Form Responses'!$I$1:$Q$200,22,$A6)&", ")),ISNUMBER(SEARCH(", "&$B6&", ", ", "&INDEX('Form Responses'!$R$1:$R$200,22)&", "))),1,"")) | Y6: =IF(Wizards!$A$23="","",IF(OR(ISNUMBER(SEARCH(", "&$B6&", ", ", "&INDEX('Form Responses'!$I$1:$Q$200,23,$A6)&", ")),ISNUMBER(SEARCH(", "&$B6&", ", ", "&INDEX('Form Responses'!$R$1:$R$200,23)&", "))),1,"")) | Z6: =IF(Wizards!$A$24="","",IF(OR(ISNUMBER(SEARCH(", "&$B6&", ", ", "&INDEX('Form Responses'!$I$1:$Q$200,24,$A6)&", ")),ISNUMBER(SEARCH(", "&$B6&", ", ", "&INDEX('Form Responses'!$R$1:$R$200,24)&", "))),1,"")) | AA6: =IF(Wizards!$A$25="","",IF(OR(ISNUMBER(SEARCH(", "&$B6&", ", ", "&INDEX('Form Responses'!$I$1:$Q$200,25,$A6)&", ")),ISNUMBER(SEARCH(", "&$B6&", ", ", "&INDEX('Form Responses'!$R$1:$R$200,25)&", "))),1,"")) | AB6: =IF(D6=1,", "&D$1,"") | AC6: =IF(E6=1,", "&E$1,"") | AD6: =IF(F6=1,", "&F$1,"") | AE6: =IF(G6=1,", "&G$1,"") | AF6: =IF(H6=1,", "&H$1,"") | AG6: =IF(I6=1,", "&I$1,"") | AH6: =IF(J6=1,", "&J$1,"") | AI6: =IF(K6=1,", "&K$1,"") | ... AY6: =IF(AA6=1,", "&AA$1,"") | AZ6: =MID($AB6&$AC6&$AD6&$AE6&$AF6&$AG6&$AH6&$AI6&$AJ6&$AK6&$AL6&$AM6&$AN6&$AO6&$AP6&$AQ6&$AR6&$AS6&$AT6&$AU6&$AV6&$AW6&$AX6&$AY6,3,32767) | BA6: =COUNT($D6:$AA6)
A7: 1 | B7: Charm Person | C7: Enchantment | D7: =IF(Wizards!$A$2="","",IF(OR(ISNUMBER(SEARCH(", "&$B7&", ", ", "&INDEX('Form Responses'!$I$1:$Q$200,2,$A7)&", ")),ISNUMBER(SEARCH(", "&$B7&", ", ", "&INDEX('Form Responses'!$R$1:$R$200,2)&", "))),1,"")) | E7: =IF(Wizards!$A$3="","",IF(OR(ISNUMBER(SEARCH(", "&$B7&", ", ", "&INDEX('Form Responses'!$I$1:$Q$200,3,$A7)&", ")),ISNUMBER(SEARCH(", "&$B7&", ", ", "&INDEX('Form Responses'!$R$1:$R$200,3)&", "))),1,"")) | F7: =IF(Wizards!$A$4="","",IF(OR(ISNUMBER(SEARCH(", "&$B7&", ", ", "&INDEX('Form Responses'!$I$1:$Q$200,4,$A7)&", ")),ISNUMBER(SEARCH(", "&$B7&", ", ", "&INDEX('Form Responses'!$R$1:$R$200,4)&", "))),1,"")) | G7: =IF(Wizards!$A$5="","",IF(OR(ISNUMBER(SEARCH(", "&$B7&", ", ", "&INDEX('Form Responses'!$I$1:$Q$200,5,$A7)&", ")),ISNUMBER(SEARCH(", "&$B7&", ", ", "&INDEX('Form Responses'!$R$1:$R$200,5)&", "))),1,"")) | H7: =IF(Wizards!$A$6="","",IF(OR(ISNUMBER(SEARCH(", "&$B7&", ", ", "&INDEX('Form Responses'!$I$1:$Q$200,6,$A7)&", ")),ISNUMBER(SEARCH(", "&$B7&", ", ", "&INDEX('Form Responses'!$R$1:$R$200,6)&", "))),1,"")) | I7: =IF(Wizards!$A$7="","",IF(OR(ISNUMBER(SEARCH(", "&$B7&", ", ", "&INDEX('Form Responses'!$I$1:$Q$200,7,$A7)&", ")),ISNUMBER(SEARCH(", "&$B7&", ", ", "&INDEX('Form Responses'!$R$1:$R$200,7)&", "))),1,"")) | J7: =IF(Wizards!$A$8="","",IF(OR(ISNUMBER(SEARCH(", "&$B7&", ", ", "&INDEX('Form Responses'!$I$1:$Q$200,8,$A7)&", ")),ISNUMBER(SEARCH(", "&$B7&", ", ", "&INDEX('Form Responses'!$R$1:$R$200,8)&", "))),1,"")) | K7: =IF(Wizards!$A$9="","",IF(OR(ISNUMBER(SEARCH(", "&$B7&", ", ", "&INDEX('Form Responses'!$I$1:$Q$200,9,$A7)&", ")),ISNUMBER(SEARCH(", "&$B7&", ", ", "&INDEX('Form Responses'!$R$1:$R$200,9)&", "))),1,"")) | L7: =IF(Wizards!$A$10="","",IF(OR(ISNUMBER(SEARCH(", "&$B7&", ", ", "&INDEX('Form Responses'!$I$1:$Q$200,10,$A7)&", ")),ISNUMBER(SEARCH(", "&$B7&", ", ", "&INDEX('Form Responses'!$R$1:$R$200,10)&", "))),1,"")) | M7: =IF(Wizards!$A$11="","",IF(OR(ISNUMBER(SEARCH(", "&$B7&", ", ", "&INDEX('Form Responses'!$I$1:$Q$200,11,$A7)&", ")),ISNUMBER(SEARCH(", "&$B7&", ", ", "&INDEX('Form Responses'!$R$1:$R$200,11)&", "))),1,"")) | N7: =IF(Wizards!$A$12="","",IF(OR(ISNUMBER(SEARCH(", "&$B7&", ", ", "&INDEX('Form Responses'!$I$1:$Q$200,12,$A7)&", ")),ISNUMBER(SEARCH(", "&$B7&", ", ", "&INDEX('Form Responses'!$R$1:$R$200,12)&", "))),1,"")) | O7: =IF(Wizards!$A$13="","",IF(OR(ISNUMBER(SEARCH(", "&$B7&", ", ", "&INDEX('Form Responses'!$I$1:$Q$200,13,$A7)&", ")),ISNUMBER(SEARCH(", "&$B7&", ", ", "&INDEX('Form Responses'!$R$1:$R$200,13)&", "))),1,"")) | P7: =IF(Wizards!$A$14="","",IF(OR(ISNUMBER(SEARCH(", "&$B7&", ", ", "&INDEX('Form Responses'!$I$1:$Q$200,14,$A7)&", ")),ISNUMBER(SEARCH(", "&$B7&", ", ", "&INDEX('Form Responses'!$R$1:$R$200,14)&", "))),1,"")) | Q7: =IF(Wizards!$A$15="","",IF(OR(ISNUMBER(SEARCH(", "&$B7&", ", ", "&INDEX('Form Responses'!$I$1:$Q$200,15,$A7)&", ")),ISNUMBER(SEARCH(", "&$B7&", ", ", "&INDEX('Form Responses'!$R$1:$R$200,15)&", "))),1,"")) | R7: =IF(Wizards!$A$16="","",IF(OR(ISNUMBER(SEARCH(", "&$B7&", ", ", "&INDEX('Form Responses'!$I$1:$Q$200,16,$A7)&", ")),ISNUMBER(SEARCH(", "&$B7&", ", ", "&INDEX('Form Responses'!$R$1:$R$200,16)&", "))),1,"")) | S7: =IF(Wizards!$A$17="","",IF(OR(ISNUMBER(SEARCH(", "&$B7&", ", ", "&INDEX('Form Responses'!$I$1:$Q$200,17,$A7)&", ")),ISNUMBER(SEARCH(", "&$B7&", ", ", "&INDEX('Form Responses'!$R$1:$R$200,17)&", "))),1,"")) | T7: =IF(Wizards!$A$18="","",IF(OR(ISNUMBER(SEARCH(", "&$B7&", ", ", "&INDEX('Form Responses'!$I$1:$Q$200,18,$A7)&", ")),ISNUMBER(SEARCH(", "&$B7&", ", ", "&INDEX('Form Responses'!$R$1:$R$200,18)&", "))),1,"")) | U7: =IF(Wizards!$A$19="","",IF(OR(ISNUMBER(SEARCH(", "&$B7&", ", ", "&INDEX('Form Responses'!$I$1:$Q$200,19,$A7)&", ")),ISNUMBER(SEARCH(", "&$B7&", ", ", "&INDEX('Form Responses'!$R$1:$R$200,19)&", "))),1,"")) | V7: =IF(Wizards!$A$20="","",IF(OR(ISNUMBER(SEARCH(", "&$B7&", ", ", "&INDEX('Form Responses'!$I$1:$Q$200,20,$A7)&", ")),ISNUMBER(SEARCH(", "&$B7&", ", ", "&INDEX('Form Responses'!$R$1:$R$200,20)&", "))),1,"")) | W7: =IF(Wizards!$A$21="","",IF(OR(ISNUMBER(SEARCH(", "&$B7&", ", ", "&INDEX('Form Responses'!$I$1:$Q$200,21,$A7)&", ")),ISNUMBER(SEARCH(", "&$B7&", ", ", "&INDEX('Form Responses'!$R$1:$R$200,21)&", "))),1,"")) | X7: =IF(Wizards!$A$22="","",IF(OR(ISNUMBER(SEARCH(", "&$B7&", ", ", "&INDEX('Form Responses'!$I$1:$Q$200,22,$A7)&", ")),ISNUMBER(SEARCH(", "&$B7&", ", ", "&INDEX('Form Responses'!$R$1:$R$200,22)&", "))),1,"")) | Y7: =IF(Wizards!$A$23="","",IF(OR(ISNUMBER(SEARCH(", "&$B7&", ", ", "&INDEX('Form Responses'!$I$1:$Q$200,23,$A7)&", ")),ISNUMBER(SEARCH(", "&$B7&", ", ", "&INDEX('Form Responses'!$R$1:$R$200,23)&", "))),1,"")) | Z7: =IF(Wizards!$A$24="","",IF(OR(ISNUMBER(SEARCH(", "&$B7&", ", ", "&INDEX('Form Responses'!$I$1:$Q$200,24,$A7)&", ")),ISNUMBER(SEARCH(", "&$B7&", ", ", "&INDEX('Form Responses'!$R$1:$R$200,24)&", "))),1,"")) | AA7: =IF(Wizards!$A$25="","",IF(OR(ISNUMBER(SEARCH(", "&$B7&", ", ", "&INDEX('Form Responses'!$I$1:$Q$200,25,$A7)&", ")),ISNUMBER(SEARCH(", "&$B7&", ", ", "&INDEX('Form Responses'!$R$1:$R$200,25)&", "))),1,"")) | AB7: =IF(D7=1,", "&D$1,"") | AC7: =IF(E7=1,", "&E$1,"") | AD7: =IF(F7=1,", "&F$1,"") | AE7: =IF(G7=1,", "&G$1,"") | AF7: =IF(H7=1,", "&H$1,"") | AG7: =IF(I7=1,", "&I$1,"") | AH7: =IF(J7=1,", "&J$1,"") | AI7: =IF(K7=1,", "&K$1,"") | ... AY7: =IF(AA7=1,", "&AA$1,"") | AZ7: =MID($AB7&$AC7&$AD7&$AE7&$AF7&$AG7&$AH7&$AI7&$AJ7&$AK7&$AL7&$AM7&$AN7&$AO7&$AP7&$AQ7&$AR7&$AS7&$AT7&$AU7&$AV7&$AW7&$AX7&$AY7,3,32767) | BA7: =COUNT($D7:$AA7)
A8: 1 | B8: Chromatic Orb | C8: Evocation | D8: =IF(Wizards!$A$2="","",IF(OR(ISNUMBER(SEARCH(", "&$B8&", ", ", "&INDEX('Form Responses'!$I$1:$Q$200,2,$A8)&", ")),ISNUMBER(SEARCH(", "&$B8&", ", ", "&INDEX('Form Responses'!$R$1:$R$200,2)&", "))),1,"")) | E8: =IF(Wizards!$A$3="","",IF(OR(ISNUMBER(SEARCH(", "&$B8&", ", ", "&INDEX('Form Responses'!$I$1:$Q$200,3,$A8)&", ")),ISNUMBER(SEARCH(", "&$B8&", ", ", "&INDEX('Form Responses'!$R$1:$R$200,3)&", "))),1,"")) | F8: =IF(Wizards!$A$4="","",IF(OR(ISNUMBER(SEARCH(", "&$B8&", ", ", "&INDEX('Form Responses'!$I$1:$Q$200,4,$A8)&", ")),ISNUMBER(SEARCH(", "&$B8&", ", ", "&INDEX('Form Responses'!$R$1:$R$200,4)&", "))),1,"")) | G8: =IF(Wizards!$A$5="","",IF(OR(ISNUMBER(SEARCH(", "&$B8&", ", ", "&INDEX('Form Responses'!$I$1:$Q$200,5,$A8)&", ")),ISNUMBER(SEARCH(", "&$B8&", ", ", "&INDEX('Form Responses'!$R$1:$R$200,5)&", "))),1,"")) | H8: =IF(Wizards!$A$6="","",IF(OR(ISNUMBER(SEARCH(", "&$B8&", ", ", "&INDEX('Form Responses'!$I$1:$Q$200,6,$A8)&", ")),ISNUMBER(SEARCH(", "&$B8&", ", ", "&INDEX('Form Responses'!$R$1:$R$200,6)&", "))),1,"")) | I8: =IF(Wizards!$A$7="","",IF(OR(ISNUMBER(SEARCH(", "&$B8&", ", ", "&INDEX('Form Responses'!$I$1:$Q$200,7,$A8)&", ")),ISNUMBER(SEARCH(", "&$B8&", ", ", "&INDEX('Form Responses'!$R$1:$R$200,7)&", "))),1,"")) | J8: =IF(Wizards!$A$8="","",IF(OR(ISNUMBER(SEARCH(", "&$B8&", ", ", "&INDEX('Form Responses'!$I$1:$Q$200,8,$A8)&", ")),ISNUMBER(SEARCH(", "&$B8&", ", ", "&INDEX('Form Responses'!$R$1:$R$200,8)&", "))),1,"")) | K8: =IF(Wizards!$A$9="","",IF(OR(ISNUMBER(SEARCH(", "&$B8&", ", ", "&INDEX('Form Responses'!$I$1:$Q$200,9,$A8)&", ")),ISNUMBER(SEARCH(", "&$B8&", ", ", "&INDEX('Form Responses'!$R$1:$R$200,9)&", "))),1,"")) | L8: =IF(Wizards!$A$10="","",IF(OR(ISNUMBER(SEARCH(", "&$B8&", ", ", "&INDEX('Form Responses'!$I$1:$Q$200,10,$A8)&", ")),ISNUMBER(SEARCH(", "&$B8&", ", ", "&INDEX('Form Responses'!$R$1:$R$200,10)&", "))),1,"")) | M8: =IF(Wizards!$A$11="","",IF(OR(ISNUMBER(SEARCH(", "&$B8&", ", ", "&INDEX('Form Responses'!$I$1:$Q$200,11,$A8)&", ")),ISNUMBER(SEARCH(", "&$B8&", ", ", "&INDEX('Form Responses'!$R$1:$R$200,11)&", "))),1,"")) | N8: =IF(Wizards!$A$12="","",IF(OR(ISNUMBER(SEARCH(", "&$B8&", ", ", "&INDEX('Form Responses'!$I$1:$Q$200,12,$A8)&", ")),ISNUMBER(SEARCH(", "&$B8&", ", ", "&INDEX('Form Responses'!$R$1:$R$200,12)&", "))),1,"")) | O8: =IF(Wizards!$A$13="","",IF(OR(ISNUMBER(SEARCH(", "&$B8&", ", ", "&INDEX('Form Responses'!$I$1:$Q$200,13,$A8)&", ")),ISNUMBER(SEARCH(", "&$B8&", ", ", "&INDEX('Form Responses'!$R$1:$R$200,13)&", "))),1,"")) | P8: =IF(Wizards!$A$14="","",IF(OR(ISNUMBER(SEARCH(", "&$B8&", ", ", "&INDEX('Form Responses'!$I$1:$Q$200,14,$A8)&", ")),ISNUMBER(SEARCH(", "&$B8&", ", ", "&INDEX('Form Responses'!$R$1:$R$200,14)&", "))),1,"")) | Q8: =IF(Wizards!$A$15="","",IF(OR(ISNUMBER(SEARCH(", "&$B8&", ", ", "&INDEX('Form Responses'!$I$1:$Q$200,15,$A8)&", ")),ISNUMBER(SEARCH(", "&$B8&", ", ", "&INDEX('Form Responses'!$R$1:$R$200,15)&", "))),1,"")) | R8: =IF(Wizards!$A$16="","",IF(OR(ISNUMBER(SEARCH(", "&$B8&", ", ", "&INDEX('Form Responses'!$I$1:$Q$200,16,$A8)&", ")),ISNUMBER(SEARCH(", "&$B8&", ", ", "&INDEX('Form Responses'!$R$1:$R$200,16)&", "))),1,"")) | S8: =IF(Wizards!$A$17="","",IF(OR(ISNUMBER(SEARCH(", "&$B8&", ", ", "&INDEX('Form Responses'!$I$1:$Q$200,17,$A8)&", ")),ISNUMBER(SEARCH(", "&$B8&", ", ", "&INDEX('Form Responses'!$R$1:$R$200,17)&", "))),1,"")) | T8: =IF(Wizards!$A$18="","",IF(OR(ISNUMBER(SEARCH(", "&$B8&", ", ", "&INDEX('Form Responses'!$I$1:$Q$200,18,$A8)&", ")),ISNUMBER(SEARCH(", "&$B8&", ", ", "&INDEX('Form Responses'!$R$1:$R$200,18)&", "))),1,"")) | U8: =IF(Wizards!$A$19="","",IF(OR(ISNUMBER(SEARCH(", "&$B8&", ", ", "&INDEX('Form Responses'!$I$1:$Q$200,19,$A8)&", ")),ISNUMBER(SEARCH(", "&$B8&", ", ", "&INDEX('Form Responses'!$R$1:$R$200,19)&", "))),1,"")) | V8: =IF(Wizards!$A$20="","",IF(OR(ISNUMBER(SEARCH(", "&$B8&", ", ", "&INDEX('Form Responses'!$I$1:$Q$200,20,$A8)&", ")),ISNUMBER(SEARCH(", "&$B8&", ", ", "&INDEX('Form Responses'!$R$1:$R$200,20)&", "))),1,"")) | W8: =IF(Wizards!$A$21="","",IF(OR(ISNUMBER(SEARCH(", "&$B8&", ", ", "&INDEX('Form Responses'!$I$1:$Q$200,21,$A8)&", ")),ISNUMBER(SEARCH(", "&$B8&", ", ", "&INDEX('Form Responses'!$R$1:$R$200,21)&", "))),1,"")) | X8: =IF(Wizards!$A$22="","",IF(OR(ISNUMBER(SEARCH(", "&$B8&", ", ", "&INDEX('Form Responses'!$I$1:$Q$200,22,$A8)&", ")),ISNUMBER(SEARCH(", "&$B8&", ", ", "&INDEX('Form Responses'!$R$1:$R$200,22)&", "))),1,"")) | Y8: =IF(Wizards!$A$23="","",IF(OR(ISNUMBER(SEARCH(", "&$B8&", ", ", "&INDEX('Form Responses'!$I$1:$Q$200,23,$A8)&", ")),ISNUMBER(SEARCH(", "&$B8&", ", ", "&INDEX('Form Responses'!$R$1:$R$200,23)&", "))),1,"")) | Z8: =IF(Wizards!$A$24="","",IF(OR(ISNUMBER(SEARCH(", "&$B8&", ", ", "&INDEX('Form Responses'!$I$1:$Q$200,24,$A8)&", ")),ISNUMBER(SEARCH(", "&$B8&", ", ", "&INDEX('Form Responses'!$R$1:$R$200,24)&", "))),1,"")) | AA8: =IF(Wizards!$A$25="","",IF(OR(ISNUMBER(SEARCH(", "&$B8&", ", ", "&INDEX('Form Responses'!$I$1:$Q$200,25,$A8)&", ")),ISNUMBER(SEARCH(", "&$B8&", ", ", "&INDEX('Form Responses'!$R$1:$R$200,25)&", "))),1,"")) | AB8: =IF(D8=1,", "&D$1,"") | AC8: =IF(E8=1,", "&E$1,"") | AD8: =IF(F8=1,", "&F$1,"") | AE8: =IF(G8=1,", "&G$1,"") | AF8: =IF(H8=1,", "&H$1,"") | AG8: =IF(I8=1,", "&I$1,"") | AH8: =IF(J8=1,", "&J$1,"") | AI8: =IF(K8=1,", "&K$1,"") | ... AY8: =IF(AA8=1,", "&AA$1,"") | AZ8: =MID($AB8&$AC8&$AD8&$AE8&$AF8&$AG8&$AH8&$AI8&$AJ8&$AK8&$AL8&$AM8&$AN8&$AO8&$AP8&$AQ8&$AR8&$AS8&$AT8&$AU8&$AV8&$AW8&$AX8&$AY8,3,32767) | BA8: =COUNT($D8:$AA8)
